<?xml version="1.0" encoding="utf-8"?>
<!-- =================================================================================== -->
<!-- |    This document was autogenerated by xacro from singlearm.xacro                 | -->
<!-- |    EDITING THIS FILE BY HAND IS NOT RECOMMENDED                                 | -->
<!-- =================================================================================== -->
<robot name="singlearm">
  <!-- ros_control plugin -->
  <gazebo>
    <plugin filename="libgazebo_ros_control.so" name="gazebo_ros_control">
      <robotNamespace>/singlearm</robotNamespace>
      <robotSimType>gazebo_ros_control/DefaultRobotHWSim</robotSimType>
      <controlPeriod>0.001</controlPeriod>
    </plugin>
  </gazebo>
  <!-- Base parts -->
  <link name="world"/>
  <joint name="base_joint" type="fixed">
    <origin rpy="0 0 0" xyz="0 0 0"/>
    <parent link="world"/>
    <child link="base_link"/>
  </joint>
  <link name="base_link">
    <inertial>
      <mass value="100.0"/>
      <origin rpy="0 0 0" xyz="0 0 0"/>
      <inertia ixx="0.0" ixy="0.0" ixz="0.0" iyy="0.0" iyz="0.0" izz="0.0"/>
    </inertial>
    <!--<collision>
        <origin
                rpy="${vis_rpy}"
                xyz="${vis_xyz}" />
        <geometry>
          <mesh
                  filename="${mesh_file}"
                  scale="${mesh_scale}"/>
        </geometry>
      </collision>-->
    <visual>
      <origin rpy="0 0 0" xyz="0 0 0"/>
      <geometry>
        <mesh filename="package://singlearm_description/meshes/base_link.STL" scale="0.001 0.001 0.001"/>
      </geometry>
    </visual>
  </link>
  <joint name="joint1" type="revolute">
    <axis xyz="0 0 -1"/>
    <limit effort="300" lower="0" upper="2.09439333333" velocity="1"/>
    <origin rpy="0 0 0" xyz="0.184 0 1.437"/>
    <parent link="base_link"/>
    <child link="link_01"/>
    <dynamics damping="0.1" friction="0.1"/>
  </joint>
  <transmission name="trans_joint1">
    <type>transmission_interface/SimpleTransmission</type>
    <joint name="joint1">
      <hardwareInterface>hardware_interface/EffortJointInterface</hardwareInterface>
    </joint>
    <actuator name="motor_joint1">
      <hardwareInterface>hardware_interface/EffortJointInterface</hardwareInterface>
      <mechanicalReduction>1</mechanicalReduction>
    </actuator>
  </transmission>
  <link name="link_01">
    <inertial>
      <mass value="3.2322"/>
      <origin rpy="0 0 0" xyz="0 0 0"/>
      <inertia ixx="0.096344" ixy="2.3e-05" ixz="0.0372953" iyy="0.1127698" iyz="1e-07" izz="0.0226937"/>
    </inertial>
    <!--<collision>
        <origin
                rpy="${vis_rpy}"
                xyz="${vis_xyz}" />
        <geometry>
          <mesh
                  filename="${mesh_file}"
                  scale="${mesh_scale}"/>
        </geometry>
      </collision>-->
    <visual>
      <origin rpy="0 0 0" xyz="0 0 0"/>
      <geometry>
        <mesh filename="package://singlearm_description/meshes/L1.STL" scale="0.001 0.001 0.001"/>
      </geometry>
    </visual>
  </link>
  <joint name="joint2" type="revolute">
    <axis xyz="-1 0 0"/>
    <limit effort="300" lower="-1.570795" upper="1.04719666667" velocity="1"/>
    <origin rpy="0 0 0" xyz="0.122 0 0.0643"/>
    <parent link="link_01"/>
    <child link="link_02"/>
    <dynamics damping="0.1" friction="0.1"/>
  </joint>
  <transmission name="trans_joint2">
    <type>transmission_interface/SimpleTransmission</type>
    <joint name="joint2">
      <hardwareInterface>hardware_interface/EffortJointInterface</hardwareInterface>
    </joint>
    <actuator name="motor_joint2">
      <hardwareInterface>hardware_interface/EffortJointInterface</hardwareInterface>
      <mechanicalReduction>1</mechanicalReduction>
    </actuator>
  </transmission>
  <link name="link_02">
    <inertial>
      <mass value="3.2103"/>
      <origin rpy="0 0 0" xyz="0 0 0"/>
      <inertia ixx="0.1015479" ixy="0.0108557" ixz="0.1068677" iyy="0.2232514" iyz="0.0092987" izz="0.130574"/>
    </inertial>
    <!--<collision>
        <origin
                rpy="${vis_rpy}"
                xyz="${vis_xyz}" />
        <geometry>
          <mesh
                  filename="${mesh_file}"
                  scale="${mesh_scale}"/>
        </geometry>
      </collision>-->
    <visual>
      <origin rpy="0 0 0" xyz="0 0 0"/>
      <geometry>
        <mesh filename="package://singlearm_description/meshes/L2.STL" scale="0.001 0.001 0.001"/>
      </geometry>
    </visual>
  </link>
  <joint name="joint3" type="revolute">
    <axis xyz="0 -1 0"/>
    <limit effort="300" lower="-0.349065555556" upper="1.570795" velocity="1"/>
    <origin rpy="0 0 0" xyz="0.078 0 0"/>
    <parent link="link_02"/>
    <child link="link_03"/>
    <dynamics damping="0.1" friction="0.1"/>
  </joint>
  <transmission name="trans_joint3">
    <type>transmission_interface/SimpleTransmission</type>
    <joint name="joint3">
      <hardwareInterface>hardware_interface/EffortJointInterface</hardwareInterface>
    </joint>
    <actuator name="motor_joint3">
      <hardwareInterface>hardware_interface/EffortJointInterface</hardwareInterface>
      <mechanicalReduction>1</mechanicalReduction>
    </actuator>
  </transmission>
  <link name="link_03">
    <inertial>
      <mass value="2.5796"/>
      <origin rpy="0 0 0" xyz="0 0 0"/>
      <inertia ixx="0.0206408" ixy="0.0007994" ixz="-0.0017107" iyy="0.1212655" iyz="0.0013249" izz="0.10809"/>
    </inertial>
    <!--<collision>
        <origin
                rpy="${vis_rpy}"
                xyz="${vis_xyz}" />
        <geometry>
          <mesh
                  filename="${mesh_file}"
                  scale="${mesh_scale}"/>
        </geometry>
      </collision>-->
    <visual>
      <origin rpy="0 0 0" xyz="0 0 0"/>
      <geometry>
        <mesh filename="package://singlearm_description/meshes/L3.STL" scale="0.001 0.001 0.001"/>
      </geometry>
    </visual>
  </link>
  <joint name="joint4" type="revolute">
    <axis xyz="0 0 1"/>
    <limit effort="300" lower="0" upper="3.14159" velocity="1"/>
    <origin rpy="0 0 0" xyz="0 0 -0.252"/>
    <parent link="link_03"/>
    <child link="link_04"/>
    <dynamics damping="0.1" friction="0.1"/>
  </joint>
  <transmission name="trans_joint4">
    <type>transmission_interface/SimpleTransmission</type>
    <joint name="joint4">
      <hardwareInterface>hardware_interface/EffortJointInterface</hardwareInterface>
    </joint>
    <actuator name="motor_joint4">
      <hardwareInterface>hardware_interface/EffortJointInterface</hardwareInterface>
      <mechanicalReduction>1</mechanicalReduction>
    </actuator>
  </transmission>
  <link name="link_04">
    <inertial>
      <mass value="2.7422"/>
      <origin rpy="0 0 0" xyz="0 0 0"/>
      <inertia ixx="0.1358592" ixy="-0.0069269" ixz="-0.1013393" iyy="0.2185321" iyz="0.0093766" izz="0.0920665"/>
    </inertial>
    <!--<collision>
        <origin
                rpy="${vis_rpy}"
                xyz="${vis_xyz}" />
        <geometry>
          <mesh
                  filename="${mesh_file}"
                  scale="${mesh_scale}"/>
        </geometry>
      </collision>-->
    <visual>
      <origin rpy="0 0 0" xyz="0 0 0"/>
      <geometry>
        <mesh filename="package://singlearm_description/meshes/L4.STL" scale="0.001 0.001 0.001"/>
      </geometry>
    </visual>
  </link>
  <joint name="joint5" type="revolute">
    <axis xyz="0 1 0"/>
    <limit effort="300" lower="-1.570795" upper="0.7853975" velocity="1"/>
    <origin rpy="0 0 0" xyz="-0.0245 0 -0.148"/>
    <parent link="link_04"/>
    <child link="link_05"/>
    <dynamics damping="0.1" friction="0.1"/>
  </joint>
  <transmission name="trans_joint5">
    <type>transmission_interface/SimpleTransmission</type>
    <joint name="joint5">
      <hardwareInterface>hardware_interface/EffortJointInterface</hardwareInterface>
    </joint>
    <actuator name="motor_joint5">
      <hardwareInterface>hardware_interface/EffortJointInterface</hardwareInterface>
      <mechanicalReduction>1</mechanicalReduction>
    </actuator>
  </transmission>
  <link name="link_05">
    <inertial>
      <mass value="1.9907"/>
      <origin rpy="0 0 0" xyz="0 0 0"/>
      <inertia ixx="0.3135683" ixy="-0.000482" ixz="-0.1519997" iyy="0.3866411" iyz="0.0004299" izz="0.079726"/>
    </inertial>
    <!--<collision>
        <origin
                rpy="${vis_rpy}"
                xyz="${vis_xyz}" />
        <geometry>
          <mesh
                  filename="${mesh_file}"
                  scale="${mesh_scale}"/>
        </geometry>
      </collision>-->
    <visual>
      <origin rpy="0 0 0" xyz="0 0 0"/>
      <geometry>
        <mesh filename="package://singlearm_description/meshes/L5.STL" scale="0.001 0.001 0.001"/>
      </geometry>
    </visual>
  </link>
  <joint name="joint6" type="revolute">
    <axis xyz="0 0 1"/>
    <limit effort="200" lower="-0.7853975" upper="0.7853975" velocity="1"/>
    <origin rpy="0 0 0" xyz="0.0245 0 -0.2245"/>
    <parent link="link_05"/>
    <child link="link_06"/>
    <dynamics damping="0.1" friction="0.1"/>
  </joint>
  <transmission name="trans_joint6">
    <type>transmission_interface/SimpleTransmission</type>
    <joint name="joint6">
      <hardwareInterface>hardware_interface/EffortJointInterface</hardwareInterface>
    </joint>
    <actuator name="motor_joint6">
      <hardwareInterface>hardware_interface/EffortJointInterface</hardwareInterface>
      <mechanicalReduction>1</mechanicalReduction>
    </actuator>
  </transmission>
  <link name="link_06">
    <inertial>
      <mass value="0.0612"/>
      <origin rpy="0 0 0" xyz="0 0 0.2"/>
      <inertia ixx="0.0129617" ixy="0.0" ixz="0.0056294" iyy="0.0154097" iyz="0.0" izz="0.0024798"/>
    </inertial>
    <!--<collision>
        <origin
                rpy="${vis_rpy}"
                xyz="${vis_xyz}" />
        <geometry>
          <mesh
                  filename="${mesh_file}"
                  scale="${mesh_scale}"/>
        </geometry>
      </collision>-->
    <visual>
      <origin rpy="0 0 0" xyz="0 0 0"/>
      <geometry>
        <mesh filename="package://singlearm_description/meshes/L6.STL" scale="0.001 0.001 0.001"/>
      </geometry>
    </visual>
  </link>
</robot>

